Workbook

Sheet Executive Summary
A1: Campaign Performance Report — Week 1 (Dec 9–15, 2024)
A3: Key Findings
A5: Total Revenue: $631,976 | Total Ad Spend: $104,682 | Net Profit: $255,518
A6: Email is the profit engine — 56.4% margin, $0.79 CPA, contributing $133,943 in net profit.
A7: Google_Ads is the best paid channel — 6.05x ROAS, $17.07 CPA, $69,377 net profit.
A8: Facebook_Ads clears all targets (4.51x ROAS) but prospecting underperforms. Retargeting at 8.16x ROAS carries the channel.
A9: TikTok_Ads is the ONLY money-losing channel — 1.54x ROAS, $57.29 CPA, −$5,296 net profit on highest paid spend ($37,983).
A11: Channel Performance Summary
A12: Channel | B12: Revenue | C12: Spend | D12: Orders | E12: ROAS | F12: CPA | G12: Net Profit | H12: Margin
A13: Email | B13: 237630.53 | C13: 1836.76 | D13: 2335 | E13: 129.37x | F13: $0.79 | G13: 133943.08 | H13: 56.4%
A14: Google_Ads | B14: 170414.87 | C14: 28184.51 | D14: 1651 | E14: 6.05x | F14: $17.07 | G14: 69377.155 | H14: 40.7%
A15: Facebook_Ads | B15: 165482.75 | C15: 36678.01 | D15: 1674 | E15: 4.51x | F15: $21.91 | G15: 57493.778 | H15: 34.7%
A16: TikTok_Ads | B16: 58447.71 | C16: 37982.97 | D16: 663 | E16: 1.54x | F16: $57.29 | G16: -5295.9585 | H16: -9.1%
A17: TOTAL | B17: 631975.86 | C17: 104682.25 | D17: 6323 | E17: 6.04x | F17: $16.56 | G17: 255518.06 | H17: 40.4%
A19: Budget Reallocation Proposal
A20: Channel | B20: ROAS | C20: % of 4.0x Target | D20: CPA | E20: % of $50 Max | F20: Net Profit | G20: Classification | H20: Budget Change
A21: Email | B21: 129.37x | C21: 3234% | D21: $0.79 | E21: 2% | F21: 133943 | G21: INCREASE (+15%) | H21: +$276
A22: Google_Ads | B22: 6.05x | C22: 151% | D22: $17.07 | E22: 34% | F22: 69377 | G22: INCREASE (+15%) | H22: +$4,228
A23: Facebook_Ads | B23: 4.51x | C23: 113% | D23: $21.91 | E23: 44% | F23: 57494 | G23: MAINTAIN (0%) | H23: $0
A24: TikTok_Ads | B24: 1.54x | C24: 39% | D24: $57.29 | E24: 115% | F24: -5296 | G24: DECREASE_HEAVY (−45%) | H24: −$17,092
A26: New Weekly Budget
A27: Channel | B27: Current Budget | C27: Change | D27: New Budget | E27: Classification
A28: TikTok_Ads | B28: $37,983 | C28: −$17,092 | D28: $20,890 | E28: DECREASE_HEAVY
A29: Google_Ads | B29: $28,185 | C29: +$4,228 | D29: $32,412 | E29: INCREASE
A30: Email | B30: $1,837 | C30: +$276 | D30: $2,112 | E30: INCREASE
A31: Facebook_Ads | B31: $36,678 | C31: $0 | D31: $36,678 | E31: MAINTAIN
A32: Reserve | B32: — | C32: — | D32: $12,589 | E32: Unallocated savings

Sheet Raw Data
A1: Raw Campaign Data — 70 rows, Dec 9–15, 2024
A3: date | B3: campaign_name | C3: channel | D3: segment | E3: impressions | F3: clicks | G3: conversions | H3: spend | I3: revenue | J3: orders
A4: 2024-12-09 | B4: Holiday_Sale_Prospecting | C4: Facebook_Ads | D4: New_Customers | E4: 125279 | F4: 3169 | G4: 84 | H4: 2060.43 | I4: 7714.41 | J4: 84
A5: 2024-12-09 | B5: Holiday_Sale_Retargeting | C5: Facebook_Ads | D5: Retargeting | E5: 43118 | F5: 1724 | G5: 107 | H5: 1414.17 | I5: 11542.94 | J5: 107
A6: 2024-12-09 | B6: Product_Launch_Awareness | C6: Facebook_Ads | D6: New_Customers | E6: 96975 | F6: 2205 | G6: 38 | H6: 1544.07 | I6: 3371.63 | J6: 38
A7: 2024-12-09 | B7: Brand_Search | C7: Google_Ads | D7: New_Customers | E7: 15628 | F7: 775 | G7: 95 | H7: 813.82 | I7: 9750.01 | J7: 95
A8: 2024-12-09 | B8: Shopping_Campaigns | C8: Google_Ads | D8: New_Customers | E8: 77393 | F8: 1917 | G8: 57 | H8: 1629.03 | I8: 5306.69 | J8: 57
A9: 2024-12-09 | B9: Dynamic_Remarketing | C9: Google_Ads | D9: Retargeting | E9: 36298 | F9: 1366 | G9: 71 | H9: 1297.63 | I9: 7856.04 | J9: 71
A10: 2024-12-09 | B10: Influencer_Collab_Video | C10: TikTok_Ads | D10: New_Customers | E10: 244182 | F10: 4983 | G10: 47 | H10: 2890.61 | I10: 4057.74 | J10: 47
A11: 2024-12-09 | B11: UGC_Content_Campaign | C11: TikTok_Ads | D11: New_Customers | E11: 208784 | F11: 3839 | G11: 45 | H11: 2380.65 | I11: 4104.67 | J11: 45
A12: 2024-12-09 | B12: Weekly_Newsletter | C12: Email | D12: Loyalty | F12: 14001 | G12: 297 | H12: 279.3 | I12: 29050.54 | J12: 297
A13: 2024-12-09 | B13: Abandoned_Cart_Sequence | C13: Email | D13: Retargeting | F13: 2462 | G13: 84 | H13: 24.37 | I13: 9633.95 | J13: 84
A14: 2024-12-10 | B14: Holiday_Sale_Prospecting | C14: Facebook_Ads | D14: New_Customers | E14: 130163 | F14: 3293 | G14: 87 | H14: 2140.76 | I14: 8015.15 | J14: 87
A15: 2024-12-10 | B15: Holiday_Sale_Retargeting | C15: Facebook_Ads | D15: Retargeting | E15: 39463 | F15: 1578 | G15: 98 | H15: 1294.29 | I15: 10564.44 | J15: 98
A16: 2024-12-10 | B16: Product_Launch_Awareness | C16: Facebook_Ads | D16: New_Customers | E16: 98898 | F16: 2248 | G16: 39 | H16: 1574.69 | I16: 3438.51 | J16: 39
A17: 2024-12-10 | B17: Brand_Search | C17: Google_Ads | D17: New_Customers | E17: 17410 | F17: 863 | G17: 106 | H17: 906.65 | I17: 10862.09 | J17: 106
A18: 2024-12-10 | B18: Shopping_Campaigns | C18: Google_Ads | D18: New_Customers | E18: 93584 | F18: 2318 | G18: 69 | H18: 1969.82 | I18: 6416.83 | J18: 69
A19: 2024-12-10 | B19: Dynamic_Remarketing | C19: Google_Ads | D19: Retargeting | E19: 39271 | F19: 1478 | G19: 76 | H19: 1403.91 | I19: 8499.46 | J19: 76
A20: 2024-12-10 | B20: Influencer_Collab_Video | C20: TikTok_Ads | D20: New_Customers | E20: 290292 | F20: 5924 | G20: 56 | H20: 3436.45 | I20: 4823.97 | J20: 56
A21: 2024-12-10 | B21: UGC_Content_Campaign | C21: TikTok_Ads | D21: New_Customers | E21: 218783 | F21: 4023 | G21: 47 | H21: 2494.66 | I21: 4301.25 | J21: 47
A22: 2024-12-10 | B22: Weekly_Newsletter | C22: Email | D22: Loyalty | F22: 11265 | G22: 239 | H22: 224.73 | I22: 23374.21 | J22: 239
A23: 2024-12-10 | B23: Abandoned_Cart_Sequence | C23: Email | D23: Retargeting | F23: 2466 | G23: 84 | H23: 24.41 | I23: 9647.44 | J23: 84
A24: 2024-12-11 | B24: Holiday_Sale_Prospecting | C24: Facebook_Ads | D24: New_Customers | E24: 141306 | F24: 3575 | G24: 94 | H24: 2324.03 | I24: 8701.33 | J24: 94
A25: 2024-12-11 | B25: Holiday_Sale_Retargeting | C25: Facebook_Ads | D25: Retargeting | E25: 43932 | F25: 1756 | G25: 109 | H25: 1440.86 | I25: 11760.85 | J25: 109
A26: 2024-12-11 | B26: Product_Launch_Awareness | C26: Facebook_Ads | D26: New_Customers | E26: 86612 | F26: 1969 | G26: 34 | H26: 1379.06 | I26: 3011.33 | J26: 34
A27: 2024-12-11 | B27: Brand_Search | C27: Google_Ads | D27: New_Customers | E27: 14422 | F27: 715 | G27: 87 | H27: 751.06 | I27: 8998.08 | J27: 87
A28: 2024-12-11 | B28: Shopping_Campaigns | C28: Google_Ads | D28: New_Customers | E28: 80728 | F28: 1999 | G28: 59 | H28: 1699.22 | I28: 5535.35 | J28: 59
A29: 2024-12-11 | B29: Dynamic_Remarketing | C29: Google_Ads | D29: Retargeting | E29: 41764 | F29: 1571 | G29: 81 | H29: 1493.05 | I29: 9039.09 | J29: 81
A30: 2024-12-11 | B30: Influencer_Collab_Video | C30: TikTok_Ads | D30: New_Customers | E30: 288988 | F30: 5898 | G30: 56 | H30: 3421.01 | I30: 4802.29 | J30: 56
A31: 2024-12-11 | B31: UGC_Content_Campaign | C31: TikTok_Ads | D31: New_Customers | E31: 179785 | F31: 3306 | G31: 39 | H31: 2049.99 | I31: 3534.55 | J31: 39
A32: 2024-12-11 | B32: Weekly_Newsletter | C32: Email | D32: Loyalty | F32: 11140 | G32: 237 | H32: 222.24 | I32: 23115.38 | J32: 237
A33: 2024-12-11 | B33: Abandoned_Cart_Sequence | C33: Email | D33: Retargeting | F33: 2121 | G33: 72 | H33: 21 | I33: 8298.95 | J33: 72
A34: 2024-12-12 | B34: Holiday_Sale_Prospecting | C34: Facebook_Ads | D34: New_Customers | E34: 138154 | F34: 3495 | G34: 92 | H34: 2272.19 | I34: 8507.24 | J34: 92
A35: 2024-12-12 | B35: Holiday_Sale_Retargeting | C35: Facebook_Ads | D35: Retargeting | E35: 46835 | F35: 1873 | G35: 117 | H35: 1536.08 | I35: 12538.07 | J35: 117
A36: 2024-12-12 | B36: Product_Launch_Awareness | C36: Facebook_Ads | D36: New_Customers | E36: 95435 | F36: 2170 | G36: 37 | H36: 1519.55 | I36: 3318.1 | J36: 37
A37: 2024-12-12 | B37: Brand_Search | C37: Google_Ads | D37: New_Customers | E37: 15136 | F37: 750 | G37: 92 | H37: 788.21 | I37: 9443.2 | J37: 92
A38: 2024-12-12 | B38: Shopping_Campaigns | C38: Google_Ads | D38: New_Customers | E38: 79650 | F38: 1973 | G38: 58 | H38: 1676.54 | I38: 5461.45 | J38: 58
A39: 2024-12-12 | B39: Dynamic_Remarketing | C39: Google_Ads | D39: Retargeting | E39: 37349 | F39: 1405 | G39: 73 | H39: 1335.19 | I39: 8083.42 | J39: 73
A40: 2024-12-12 | B40: Influencer_Collab_Video | C40: TikTok_Ads | D40: New_Customers | E40: 242963 | F40: 4958 | G40: 47 | H40: 2876.18 | I40: 4037.48 | J40: 47
A41: 2024-12-12 | B41: UGC_Content_Campaign | C41: TikTok_Ads | D41: New_Customers | E41: 220333 | F41: 4051 | G41: 48 | H41: 2512.33 | I41: 4331.72 | J41: 48
...

Sheet Funnel Analysis
A1: Funnel Performance — CTR & CVR by Channel
A2: CTR = Clicks / Impressions | CVR = Conversions / Clicks
A4: Channel | B4: Impressions | C4: Clicks | D4: Conversions | E4: CTR | F4: CTR Bench | G4: CTR Δ | H4: CVR | I4: CVR Bench | J4: CVR Δ | K4: Verdict
A5: Email | B5: =SUMIF('Raw Data'!$C$4:$C$73,"Email",'Raw Data'!$E$4:$E$73) | C5: =SUMIF('Raw Data'!$C$4:$C$73,"Email",'Raw Data'!$F$4:$F$73) | D5: =SUMIF('Raw Data'!$C$4:$C$73,"Email",'Raw Data'!$G$4:$G$73) | E5: N/A | F5: 15.0% | G5: N/A | H5: =IF(C5=0,"",D5/C5) | I5: 2.1% | J5: =IF(OR(C5=0,H5=""),"",H5-VALUE(LEFT(I5,LEN(I5)-1))/100) | K5: CVR✓
A6: Google_Ads | B6: =SUMIF('Raw Data'!$C$4:$C$73,"Google_Ads",'Raw Data'!$E$4:$E$73) | C6: =SUMIF('Raw Data'!$C$4:$C$73,"Google_Ads",'Raw Data'!$F$4:$F$73) | D6: =SUMIF('Raw Data'!$C$4:$C$73,"Google_Ads",'Raw Data'!$G$4:$G$73) | E6: =IF(B6=0,"",C6/B6) | F6: 5.0% | G6: =IF(OR(B6=0,E6=""),"",E6-VALUE(LEFT(F6,LEN(F6)-1))/100) | H6: =IF(C6=0,"",D6/C6) | I6: 4.5% | J6: =IF(OR(C6=0,H6=""),"",H6-VALUE(LEFT(I6,LEN(I6)-1))/100) | K6: CTR✓ | CVR✓
A7: Facebook_Ads | B7: =SUMIF('Raw Data'!$C$4:$C$73,"Facebook_Ads",'Raw Data'!$E$4:$E$73) | C7: =SUMIF('Raw Data'!$C$4:$C$73,"Facebook_Ads",'Raw Data'!$F$4:$F$73) | D7: =SUMIF('Raw Data'!$C$4:$C$73,"Facebook_Ads",'Raw Data'!$G$4:$G$73) | E7: =IF(B7=0,"",C7/B7) | F7: 2.5% | G7: =IF(OR(B7=0,E7=""),"",E7-VALUE(LEFT(F7,LEN(F7)-1))/100) | H7: =IF(C7=0,"",D7/C7) | I7: 3.8% | J7: =IF(OR(C7=0,H7=""),"",H7-VALUE(LEFT(I7,LEN(I7)-1))/100) | K7: CTR✓ | CVR✓
A8: TikTok_Ads | B8: =SUMIF('Raw Data'!$C$4:$C$73,"TikTok_Ads",'Raw Data'!$E$4:$E$73) | C8: =SUMIF('Raw Data'!$C$4:$C$73,"TikTok_Ads",'Raw Data'!$F$4:$F$73) | D8: =SUMIF('Raw Data'!$C$4:$C$73,"TikTok_Ads",'Raw Data'!$G$4:$G$73) | E8: =IF(B8=0,"",C8/B8) | F8: 2.0% | G8: =IF(OR(B8=0,E8=""),"",E8-VALUE(LEFT(F8,LEN(F8)-1))/100) | H8: =IF(C8=0,"",D8/C8) | I8: 0.9% | J8: =IF(OR(C8=0,H8=""),"",H8-VALUE(LEFT(I8,LEN(I8)-1))/100) | K8: CTR✓ | CVR✓
A10: Per-Campaign Funnel Breakdown
A11: Campaign | B11: Channel | C11: Segment | D11: Impressions | E11: Clicks | F11: Conversions | G11: CTR | H11: CVR
A12: Abandoned_Cart_Sequence | B12: Email | C12: Retargeting | D12: N/A | E12: 16159 | F12: 550 | G12: N/A | H12: 3.40%
A13: Brand_Search | B13: Google_Ads | C13: New_Customers | D13: 111,144 | E13: 5509 | F13: 674 | G13: 4.96% | H13: 12.23%
A14: Dynamic_Remarketing | B14: Google_Ads | C14: Retargeting | D14: 281,213 | E14: 10580 | F14: 547 | G14: 3.76% | H14: 5.17%
A15: Holiday_Sale_Prospecting | B15: Facebook_Ads | C15: New_Customers | D15: 941,537 | E15: 23818 | F15: 629 | G15: 2.53% | H15: 2.64%
A16: Holiday_Sale_Retargeting | B16: Facebook_Ads | C16: Retargeting | D16: 312,247 | E16: 12484 | F16: 776 | G16: 4.00% | H16: 6.22%
A17: Influencer_Collab_Video | B17: TikTok_Ads | C17: New_Customers | D17: 1,856,502 | E17: 37887 | F17: 360 | G17: 2.04% | H17: 0.95%
A18: Product_Launch_Awareness | B18: Facebook_Ads | C18: New_Customers | D18: 687,828 | E18: 15638 | F18: 269 | G18: 2.27% | H18: 1.72%
A19: Shopping_Campaigns | B19: Google_Ads | C19: New_Customers | D19: 586,423 | E19: 14524 | F19: 430 | G19: 2.48% | H19: 2.96%
A20: UGC_Content_Campaign | B20: TikTok_Ads | C20: New_Customers | D20: 1,403,723 | E20: 25811 | F20: 303 | G20: 1.84% | H20: 1.17%
A21: Weekly_Newsletter | B21: Email | C21: Loyalty | D21: N/A | E21: 84054 | F21: 1785 | G21: N/A | H21: 2.12%

Sheet Efficiency Analysis
A1: Efficiency Performance — ROAS, CPA & Net Profit
A2: Shipping=$8/order | Product Cost=35% revenue | ROAS≥4.0x | CPA≤$50
A4: Channel | B4: Revenue | C4: Spend | D4: Orders | E4: ROAS | F4: Target | G4: CPA | H4: Max | I4: Shipping | J4: Product Cost | K4: Net Profit | L4: Margin | M4: Verdict
A5: Email | B5: =SUMIF('Raw Data'!$C$4:$C$73,"Email",'Raw Data'!$I$4:$I$73) | C5: =SUMIF('Raw Data'!$C$4:$C$73,"Email",'Raw Data'!$H$4:$H$73) | D5: =SUMIF('Raw Data'!$C$4:$C$73,"Email",'Raw Data'!$J$4:$J$73) | E5: =IF(C5=0,"",B5/C5) | F5: ≥4.0x | G5: =IF(=SUMIF('Raw Data'!$C$4:$C$73,"Email",'Raw Data'!$G$4:$G$73)=0,"",C5/=SUMIF('Raw Data'!$C$4:$C$73,"Email",'Raw Data'!$G$4:$G$73)) | H5: ≤$50 | I5: =D5*8.0 | J5: =B5*0.35 | K5: =B5-(C5+I5+J5) | L5: =IF(B5=0,"",K5/B5)
A6: Google_Ads | B6: =SUMIF('Raw Data'!$C$4:$C$73,"Google_Ads",'Raw Data'!$I$4:$I$73) | C6: =SUMIF('Raw Data'!$C$4:$C$73,"Google_Ads",'Raw Data'!$H$4:$H$73) | D6: =SUMIF('Raw Data'!$C$4:$C$73,"Google_Ads",'Raw Data'!$J$4:$J$73) | E6: =IF(C6=0,"",B6/C6) | F6: ≥4.0x | G6: =IF(=SUMIF('Raw Data'!$C$4:$C$73,"Google_Ads",'Raw Data'!$G$4:$G$73)=0,"",C6/=SUMIF('Raw Data'!$C$4:$C$73,"Google_Ads",'Raw Data'!$G$4:$G$73)) | H6: ≤$50 | I6: =D6*8.0 | J6: =B6*0.35 | K6: =B6-(C6+I6+J6) | L6: =IF(B6=0,"",K6/B6)
A7: Facebook_Ads | B7: =SUMIF('Raw Data'!$C$4:$C$73,"Facebook_Ads",'Raw Data'!$I$4:$I$73) | C7: =SUMIF('Raw Data'!$C$4:$C$73,"Facebook_Ads",'Raw Data'!$H$4:$H$73) | D7: =SUMIF('Raw Data'!$C$4:$C$73,"Facebook_Ads",'Raw Data'!$J$4:$J$73) | E7: =IF(C7=0,"",B7/C7) | F7: ≥4.0x | G7: =IF(=SUMIF('Raw Data'!$C$4:$C$73,"Facebook_Ads",'Raw Data'!$G$4:$G$73)=0,"",C7/=SUMIF('Raw Data'!$C$4:$C$73,"Facebook_Ads",'Raw Data'!$G$4:$G$73)) | H7: ≤$50 | I7: =D7*8.0 | J7: =B7*0.35 | K7: =B7-(C7+I7+J7) | L7: =IF(B7=0,"",K7/B7)
A8: TikTok_Ads | B8: =SUMIF('Raw Data'!$C$4:$C$73,"TikTok_Ads",'Raw Data'!$I$4:$I$73) | C8: =SUMIF('Raw Data'!$C$4:$C$73,"TikTok_Ads",'Raw Data'!$H$4:$H$73) | D8: =SUMIF('Raw Data'!$C$4:$C$73,"TikTok_Ads",'Raw Data'!$J$4:$J$73) | E8: =IF(C8=0,"",B8/C8) | F8: ≥4.0x | G8: =IF(=SUMIF('Raw Data'!$C$4:$C$73,"TikTok_Ads",'Raw Data'!$G$4:$G$73)=0,"",C8/=SUMIF('Raw Data'!$C$4:$C$73,"TikTok_Ads",'Raw Data'!$G$4:$G$73)) | H8: ≤$50 | I8: =D8*8.0 | J8: =B8*0.35 | K8: =B8-(C8+I8+J8) | L8: =IF(B8=0,"",K8/B8)
A10: Per-Campaign Efficiency Breakdown
A11: Campaign | B11: Channel | C11: Revenue | D11: Spend | E11: Orders | F11: ROAS | G11: CPA | H11: Net Profit | I11: Verdict
A12: Abandoned_Cart_Sequence | B12: Email | C12: 63223.37 | D12: 159.95 | E12: 550 | F12: 395.27x | G12: $0.29 | H12: 36535.241 | I12: ROAS✓ | CPA✓ | Profit✓
A13: Brand_Search | B13: Google_Ads | C13: 69342.09 | D13: 5787.91 | E13: 674 | F13: 11.98x | G13: $8.59 | H13: 33892.448 | I13: ROAS✓ | CPA✓ | Profit✓
A14: Dynamic_Remarketing | B14: Google_Ads | C14: 60863.01 | D14: 10053.14 | E14: 547 | F14: 6.05x | G14: $18.38 | H14: 25131.817 | I14: ROAS✓ | CPA✓ | Profit✓
A15: Holiday_Sale_Prospecting | B15: Facebook_Ads | C15: 57977.88 | D15: 15485.23 | E15: 629 | F15: 3.74x | G15: $24.62 | H15: 17168.392 | I15: ROAS✗ | CPA✓ | Profit✓
A16: Holiday_Sale_Retargeting | B16: Facebook_Ads | C16: 83590.4 | D16: 10240.96 | E16: 776 | F16: 8.16x | G16: $13.20 | H16: 37884.8 | I16: ROAS✓ | CPA✓ | Profit✓
A17: Influencer_Collab_Video | B17: TikTok_Ads | C17: 30850.69 | D17: 21977.11 | E17: 360 | F17: 1.40x | G17: $61.05 | H17: -4804.1615 | I17: ROAS✗ | CPA✗ | Profit✗
A18: Product_Launch_Awareness | B18: Facebook_Ads | C18: 23914.47 | D18: 10951.82 | E18: 269 | F18: 2.18x | G18: $40.71 | H18: 2440.5855 | I18: ROAS✗ | CPA✓ | Profit✓
A19: Shopping_Campaigns | B19: Google_Ads | C19: 40209.77 | D19: 12343.46 | E19: 430 | F19: 3.26x | G19: $28.71 | H19: 10352.89 | I19: ROAS✗ | CPA✓ | Profit✓
A20: UGC_Content_Campaign | B20: TikTok_Ads | C20: 27597.02 | D20: 16005.86 | E20: 303 | F20: 1.72x | G20: $52.82 | H20: -491.797 | I20: ROAS✗ | CPA✗ | Profit✗
A21: Weekly_Newsletter | B21: Email | C21: 174407.16 | D21: 1676.81 | E21: 1785 | F21: 104.01x | G21: $0.94 | H21: 97407.844 | I21: ROAS✓ | CPA✓ | Profit✓
A23: Profit Bridge — Where the Money Goes
A24: Channel | B24: Revenue | C24: − Spend | D24: − Shipping | E24: − Product Cost | F24: =Net Profit | G24: Margin %
A25: Email | B25: 237630.53 | C25: 1836.76 | D25: 18680 | E25: 83170.685 | F25: 133943.08 | G25: 56.4%
A26: Google_Ads | B26: 170414.87 | C26: 28184.51 | D26: 13208 | E26: 59645.204 | F26: 69377.155 | G26: 40.7%
A27: Facebook_Ads | B27: 165482.75 | C27: 36678.01 | D27: 13392 | E27: 57918.963 | F27: 57493.778 | G27: 34.7%
A28: TikTok_Ads | B28: 58447.71 | C28: 37982.97 | D28: 5304 | E28: 20456.698 | F28: -5295.9585 | G28: -9.1%
